<?xml version="1.0" ?>
<!-- =================================================================================== -->
<!-- |    This document was autogenerated by xacro from src/robot_descriptions/d1h_description/xacro/robot.xacro | -->
<!-- |    EDITING THIS FILE BY HAND IS NOT RECOMMENDED                                 | -->
<!-- =================================================================================== -->
<robot name="d1h_description">
  <link name="base_link">
    <visual>
      <origin rpy="0 0 0" xyz="0 0 0"/>
      <geometry>
        <box size="0.001 0.001 0.001"/>
      </geometry>
    </visual>
    <inertial>
      <mass value="0.001"/>
      <origin rpy="0 0 0" xyz="0 0 0"/>
      <inertia ixx="0.0001" ixy="0" ixz="0" iyy="0.0001" iyz="0" izz="0.0001"/>
    </inertial>
  </link>
  <link name="F_base_link">
    <inertial>
      <origin rpy="0 0 0" xyz="0.023013 -0.0021227 -0.019381"/>
      <mass value="12.648"/>
      <inertia ixx="0.029515" ixy="2.3402E-05" ixz="-0.00071897" iyy="0.050606" iyz="1.123E-06" izz="0.056417"/>
    </inertial>
    <visual>
      <origin rpy="0 0 0" xyz="0 0 0"/>
      <geometry>
        <mesh filename="../meshes/single_base_link.STL"/>
      </geometry>
      <material name="">
        <color rgba="0.75294 0.75294 0.75294 1"/>
      </material>
    </visual>
    <collision>
      <origin rpy="0 0 0" xyz="0 0 0"/>
      <geometry>
        <box size="0.375 0.15 0.19"/>
      </geometry>
    </collision>
    <collision>
      <origin rpy="0 0 0" xyz="0 0 -0.12"/>
      <geometry>
        <box size="0.31 0.12 0.04"/>
      </geometry>
    </collision>
  </link>
  <joint name="F_base_joint" type="fixed">
    <origin rpy="0 0 0" xyz="0 0 0"/>
    <parent link="base_link"/>
    <child link="F_base_link"/>
    <axis xyz="0 0 0"/>
  </joint>
  <link name="FL_hip">
    <inertial>
      <origin rpy="0 0 0" xyz="-0.014145 6.1243E-05 0.0053964"/>
      <mass value="1.6985"/>
      <inertia ixx="0.003158" ixy="-1.3834E-07" ixz="5.9868E-05" iyy="0.0020304" iyz="-1.5293E-06" izz="0.0017725"/>
    </inertial>
    <visual>
      <origin rpy="0 0 0" xyz="0 0 0"/>
      <geometry>
        <mesh filename="../meshes/L_hip.STL"/>
      </geometry>
      <material name="">
        <color rgba="0.75294 0.75294 0.75294 1"/>
      </material>
    </visual>
  </link>
  <joint name="FL_hip_joint" type="revolute">
    <origin rpy="1.5708 0 1.5708" xyz="0 0.0775 0"/>
    <parent link="F_base_link"/>
    <child link="FL_hip"/>
    <axis xyz="0 0 1"/>
    <dynamics damping="0" friction="0"/>
    <limit effort="60" lower="-0.7853981633974483" upper="0.7853981633974483" velocity="20"/>
  </joint>
  <link name="FL_thigh">
    <inertial>
      <origin rpy="0 0 0" xyz="0.035356 0.0049257 -0.024803"/>
      <mass value="3.2263"/>
      <inertia ixx="0.0034304" ixy="-0.00055998" ixz="9.4057E-07" iyy="0.012162" iyz="2.6278E-06" izz="0.01465"/>
    </inertial>
    <visual>
      <origin rpy="0 0 0" xyz="0 0 0"/>
      <geometry>
        <mesh filename="../meshes/L_thigh.STL"/>
      </geometry>
      <material name="">
        <color rgba="0.75294 0.75294 0.75294 1"/>
      </material>
    </visual>
    <collision>
      <origin rpy="0 0 0.262" xyz="0.05 0 0"/>
      <geometry>
        <box size="0.21 0.11 0.05"/>
      </geometry>
    </collision>
  </link>
  <joint name="FL_thigh_joint" type="revolute">
    <origin rpy="-1.5708 0 -1.5708" xyz="0.09 0 0"/>
    <parent link="FL_hip"/>
    <child link="FL_thigh"/>
    <axis xyz="0 0 1"/>
    <dynamics damping="0" friction="0"/>
    <limit effort="60" lower="-1.5707963267948966" upper="3.141592653589793" velocity="20"/>
  </joint>
  <link name="FL_calf">
    <inertial>
      <origin rpy="0 0 0" xyz="0.11782 0.0051831 0.012648"/>
      <mass value="0.48008"/>
      <inertia ixx="0.00028596" ixy="0.00014991" ixz="-0.00047417" iyy="0.0044518" iyz="1.8592E-05" izz="0.0045218"/>
    </inertial>
    <visual>
      <origin rpy="0 0 0" xyz="0 0 0"/>
      <geometry>
        <mesh filename="../meshes/L_calf.STL"/>
      </geometry>
      <material name="">
        <color rgba="0.75294 0.75294 0.75294 1"/>
      </material>
    </visual>
    <collision>
      <origin rpy="0 0 -0.08" xyz="0.12 0 0"/>
      <geometry>
        <box size="0.3 0.05 0.02"/>
      </geometry>
    </collision>
  </link>
  <joint name="FL_calf_joint" type="revolute">
    <origin rpy="0 0 0" xyz="0.25 0 0"/>
    <parent link="FL_thigh"/>
    <child link="FL_calf"/>
    <axis xyz="0 0 1"/>
    <dynamics damping="0" friction="0"/>
    <limit effort="60" lower="-2.775" upper="-0.855" velocity="20"/>
  </joint>
  <link name="FL_foot">
    <inertial>
      <origin rpy="0 0 0" xyz="-1.1947E-05 -1.9864E-05 -0.0036281"/>
      <mass value="1.5215"/>
      <inertia ixx="0.0022259" ixy="-1.4306E-07" ixz="-4.8216E-07" iyy="0.0022261" iyz="-6.5528E-07" izz="0.0041464"/>
    </inertial>
    <visual>
      <origin rpy="0 0 0" xyz="0 0 0"/>
      <geometry>
        <mesh filename="../meshes/L_foot.STL"/>
      </geometry>
      <material name="">
        <color rgba="0.75294 0.75294 0.75294 1"/>
      </material>
    </visual>
    <collision>
      <origin rpy="0 0 0" xyz="0 0 0"/>
      <geometry>
        <cylinder length="0.04" radius="0.085"/>
      </geometry>
    </collision>
  </link>
  <joint name="FL_foot_joint" type="revolute">
    <origin rpy="0 0 0" xyz="0.25 0 0.06935"/>
    <parent link="FL_calf"/>
    <child link="FL_foot"/>
    <axis xyz="0 0 1"/>
    <dynamics damping="0" friction="0"/>
    <limit effort="12" lower="-1000000.0" upper="1000000.0" velocity="12.5"/>
  </joint>
  <link name="FR_hip">
    <inertial>
      <origin rpy="0 0 0" xyz="0.014145 6.1222E-05 0.0053964"/>
      <mass value="1.6985"/>
      <inertia ixx="0.003158" ixy="1.3916E-07" ixz="-5.9867E-05" iyy="0.0020304" iyz="-1.5281E-06" izz="0.0017725"/>
    </inertial>
    <visual>
      <origin rpy="0 0 0" xyz="0 0 0"/>
      <geometry>
        <mesh filename="../meshes/R_hip.STL"/>
      </geometry>
      <material name="">
        <color rgba="0.75294 0.75294 0.75294 1"/>
      </material>
    </visual>
  </link>
  <joint name="FR_hip_joint" type="revolute">
    <origin rpy="1.5708 0 1.5708" xyz="0 -0.0775 0"/>
    <parent link="F_base_link"/>
    <child link="FR_hip"/>
    <axis xyz="0 0 1"/>
    <dynamics damping="0" friction="0"/>
    <limit effort="60" lower="-0.7853981633974483" upper="0.7853981633974483" velocity="20"/>
  </joint>
  <link name="FR_thigh">
    <inertial>
      <origin rpy="0 0 0" xyz="0.035356 0.0049257 0.024803"/>
      <mass value="3.2263"/>
      <inertia ixx="0.0034304" ixy="-0.00055998" ixz="-9.4198E-07" iyy="0.012162" iyz="-2.6258E-06" izz="0.01465"/>
    </inertial>
    <visual>
      <origin rpy="0 0 0" xyz="0 0 0"/>
      <geometry>
        <mesh filename="../meshes/R_thigh.STL"/>
      </geometry>
      <material name="">
        <color rgba="0.75294 0.75294 0.75294 1"/>
      </material>
    </visual>
    <collision>
      <origin rpy="0 0 0.262" xyz="0.05 0 0"/>
      <geometry>
        <box size="0.21 0.11 0.05"/>
      </geometry>
    </collision>
  </link>
  <joint name="FR_thigh_joint" type="revolute">
    <origin rpy="-1.5708 0 -1.5708" xyz="-0.09 0 0"/>
    <parent link="FR_hip"/>
    <child link="FR_thigh"/>
    <axis xyz="0 0 1"/>
    <dynamics damping="0" friction="0"/>
    <limit effort="60" lower="-1.5707963267948966" upper="3.141592653589793" velocity="20"/>
  </joint>
  <link name="FR_calf">
    <inertial>
      <origin rpy="0 0 0" xyz="0.11782 0.0051831 -0.012648"/>
      <mass value="0.48008"/>
      <inertia ixx="0.00028596" ixy="0.00014991" ixz="0.00047417" iyy="0.0044518" iyz="-1.8592E-05" izz="0.0045218"/>
    </inertial>
    <visual>
      <origin rpy="0 0 0" xyz="0 0 0"/>
      <geometry>
        <mesh filename="../meshes/R_calf.STL"/>
      </geometry>
      <material name="">
        <color rgba="0.75294 0.75294 0.75294 1"/>
      </material>
    </visual>
    <collision>
      <origin rpy="0 0 -0.08" xyz="0.12 0 0"/>
      <geometry>
        <box size="0.3 0.05 0.02"/>
      </geometry>
    </collision>
  </link>
  <joint name="FR_calf_joint" type="revolute">
    <origin rpy="0 0 0" xyz="0.25 0 0"/>
    <parent link="FR_thigh"/>
    <child link="FR_calf"/>
    <axis xyz="0 0 1"/>
    <dynamics damping="0" friction="0"/>
    <limit effort="60" lower="-2.775" upper="-0.855" velocity="20"/>
  </joint>
  <link name="FR_foot">
    <inertial>
      <origin rpy="0 0 0" xyz="-1.1939E-05 -1.986E-05 0.0036281"/>
      <mass value="1.5215"/>
      <inertia ixx="0.0022259" ixy="-1.4321E-07" ixz="4.8221E-07" iyy="0.0022261" iyz="6.5536E-07" izz="0.0041463"/>
    </inertial>
    <visual>
      <origin rpy="0 0 0" xyz="0 0 0"/>
      <geometry>
        <mesh filename="../meshes/R_foot.STL"/>
      </geometry>
      <material name="">
        <color rgba="0.75294 0.75294 0.75294 1"/>
      </material>
    </visual>
    <collision>
      <origin rpy="0 0 0" xyz="0 0 0"/>
      <geometry>
        <cylinder length="0.04" radius="0.085"/>
      </geometry>
    </collision>
  </link>
  <joint name="FR_foot_joint" type="revolute">
    <origin rpy="0 0 0" xyz="0.25 0 -0.06935"/>
    <parent link="FR_calf"/>
    <child link="FR_foot"/>
    <axis xyz="0 0 1"/>
    <dynamics damping="0" friction="0"/>
    <limit effort="12" lower="-1000000.0" upper="1000000.0" velocity="12.5"/>
  </joint>
</robot>
